<?xml version="1.0" ?>
<robot name="g05" xmlns:xacro="http://www.ros.org/wiki/xacro">

<xacro:include filename="$(find g05)/urdf/materials.xacro" />
<xacro:include filename="$(find g05)/urdf/g05.trans" />
<xacro:include filename="$(find g05)/urdf/g05.gazebo" />

<link name="dummy">
  <pose> 0 0 0 0 0 0 </pose>
</link>

<joint name="dummy_joint" type="fixed">
  <parent link="dummy"/>
  <child link= "base_link"/>
</joint>


<link name="base_link">
  <inertial>
    <origin xyz="0.500000000000011 0.5000000000000001 0.03990961156333847" rpy="0 0 0"/>
    <mass value="449.9286565512495"/>
    <inertia ixx="33.833339" iyy="33.833339" izz="65.771249" ixy="0.0" iyz="0.0" ixz="-0.0"/>
  </inertial>
  <visual>
    <origin xyz="0 0 0" rpy="0 0 0"/>
    <geometry>
      <mesh filename="package://g05/meshes/base_link.stl" scale="0.001 0.001 0.001"/>
    </geometry>
    <material name="silver"/>
  </visual>
  <collision>
    <origin xyz="0 0 0" rpy="0 0 0"/>
    <geometry>
      <mesh filename="package://g05/meshes/base_link.stl" scale="0.001 0.001 0.001"/>
    </geometry>
  </collision>
</link>

<link name="Revolute_2_1">
  <inertial>
    <origin xyz="-0.02796233135417625 -5.434556427097448e-08 0.07271650387425044" rpy="0 0 0"/>
    <mass value="7.57485731682547"/>
    <inertia ixx="0.056149" iyy="0.066668" izz="0.04146" ixy="-0.0" iyz="-0.0" ixz="0.014556"/>
  </inertial>
  <visual>
    <origin xyz="-0.5 -0.5 -0.2875" rpy="0 0 0"/>
    <geometry>
      <mesh filename="package://g05/meshes/Revolute_2_1.stl" scale="0.001 0.001 0.001"/>
    </geometry>
    <material name="silver"/>
  </visual>
  <collision>
    <origin xyz="-0.5 -0.5 -0.2875" rpy="0 0 0"/>
    <geometry>
      <mesh filename="package://g05/meshes/Revolute_2_1.stl" scale="0.001 0.001 0.001"/>
    </geometry>
  </collision>
</link>

<link name="Revolute_3_1">
  <inertial>
    <origin xyz="0.014413868593585288 2.744690474898448e-07 0.13813231624974515" rpy="0 0 0"/>
    <mass value="4.960455877927692"/>
    <inertia ixx="0.078668" iyy="0.072525" izz="0.01127" ixy="-0.0" iyz="0.0" ixz="-0.000768"/>
  </inertial>
  <visual>
    <origin xyz="-0.312 -0.5 -0.426066" rpy="0 0 0"/>
    <geometry>
      <mesh filename="package://g05/meshes/Revolute_3_1.stl" scale="0.001 0.001 0.001"/>
    </geometry>
    <material name="silver"/>
  </visual>
  <collision>
    <origin xyz="-0.312 -0.5 -0.426066" rpy="0 0 0"/>
    <geometry>
      <mesh filename="package://g05/meshes/Revolute_3_1.stl" scale="0.001 0.001 0.001"/>
    </geometry>
  </collision>
</link>

<link name="Revolute_4_1">
  <inertial>
    <origin xyz="0.05058795204654243 2.74474345363096e-07 0.06441243873672076" rpy="0 0 0"/>
    <mass value="4.521795512874398"/>
    <inertia ixx="0.024373" iyy="0.030228" izz="0.018236" ixy="-0.0" iyz="0.0" ixz="-0.008608"/>
  </inertial>
  <visual>
    <origin xyz="-0.412 -0.5 -0.716066" rpy="0 0 0"/>
    <geometry>
      <mesh filename="package://g05/meshes/Revolute_4_1.stl" scale="0.001 0.001 0.001"/>
    </geometry>
    <material name="silver"/>
  </visual>
  <collision>
    <origin xyz="-0.412 -0.5 -0.716066" rpy="0 0 0"/>
    <geometry>
      <mesh filename="package://g05/meshes/Revolute_4_1.stl" scale="0.001 0.001 0.001"/>
    </geometry>
  </collision>
</link>

<link name="Revolute_5_1">
  <inertial>
    <origin xyz="-6.994329779241859e-07 2.7778302158498747e-07 0.010271401412828673" rpy="0 0 0"/>
    <mass value="1.5444031425616112"/>
    <inertia ixx="0.004247" iyy="0.004332" izz="0.003152" ixy="-0.0" iyz="-0.0" ixz="0.0"/>
  </inertial>
  <visual>
    <origin xyz="-0.499934 -0.5 -0.94" rpy="0 0 0"/>
    <geometry>
      <mesh filename="package://g05/meshes/Revolute_5_1.stl" scale="0.001 0.001 0.001"/>
    </geometry>
    <material name="silver"/>
  </visual>
  <collision>
    <origin xyz="-0.499934 -0.5 -0.94" rpy="0 0 0"/>
    <geometry>
      <mesh filename="package://g05/meshes/Revolute_5_1.stl" scale="0.001 0.001 0.001"/>
    </geometry>
  </collision>
</link>

<link name="end_effector_1">
  <inertial>
    <origin xyz="4.928266761905498e-07 -2.7460793233791136e-07 0.022999999999999687" rpy="0 0 0"/>
    <mass value="0.02081305133003231"/>
    <inertia ixx="4e-06" iyy="4e-06" izz="3e-06" ixy="0.0" iyz="0.0" ixz="-0.0"/>
  </inertial>
  <visual>
    <origin xyz="-0.499934 -0.5 -1.08" rpy="0 0 0"/>
    <geometry>
      <mesh filename="package://g05/meshes/end_effector_1.stl" scale="0.001 0.001 0.001"/>
    </geometry>
    <material name="silver"/>
  </visual>
  <collision>
    <origin xyz="-0.499934 -0.5 -1.08" rpy="0 0 0"/>
    <geometry>
      <mesh filename="package://g05/meshes/end_effector_1.stl" scale="0.001 0.001 0.001"/>
    </geometry>
  </collision>
</link>

<link name="Revolute_6_1">
  <inertial>
    <origin xyz="0.03497844973052605 -4.9620073327982794e-08 0.009209509656326942" rpy="0 0 0"/>
    <mass value="0.12916779249875357"/>
    <inertia ixx="6.2e-05" iyy="7.6e-05" izz="4.4e-05" ixy="0.0" iyz="0.0" ixz="-0.0"/>
  </inertial>
  <visual>
    <origin xyz="-0.464934 -0.5 -1.05" rpy="0 0 0"/>
    <geometry>
      <mesh filename="package://g05/meshes/Revolute_6_1.stl" scale="0.001 0.001 0.001"/>
    </geometry>
    <material name="silver"/>
  </visual>
  <collision>
    <origin xyz="-0.464934 -0.5 -1.05" rpy="0 0 0"/>
    <geometry>
      <mesh filename="package://g05/meshes/Revolute_6_1.stl" scale="0.001 0.001 0.001"/>
    </geometry>
  </collision>
</link>

<joint name="Revolute_1" type="continuous">
  <origin xyz="0.5 0.5 0.2875" rpy="0 0 0"/>
  <parent link="base_link"/>
  <child link="Revolute_2_1"/>
  <axis xyz="0.0 0.0 1.0"/>
</joint>

<joint name="Revolute_2" type="continuous">
  <origin xyz="-0.188 0.0 0.138566" rpy="0 0 0"/>
  <parent link="Revolute_2_1"/>
  <child link="Revolute_3_1"/>
  <axis xyz="-1.0 0.0 0.0"/>

</joint>

<joint name="Revolute_3" type="continuous">
  <origin xyz="0.1 0.0 0.29" rpy="0 0 0"/>
  <parent link="Revolute_3_1"/>
  <child link="Revolute_4_1"/>
  <axis xyz="1.0 0.0 0.0"/>
</joint>

<joint name="Revolute_4" type="continuous">
  <origin xyz="0.087934 0.0 0.223934" rpy="0 0 0"/>
  <parent link="Revolute_4_1"/>
  <child link="Revolute_5_1"/>
  <axis xyz="0.0 0.0 1.0"/>
</joint>

<joint name="Revolute_7" type="continuous">
  <origin xyz="0.035 0.0 0.03" rpy="0 0 0"/>
  <parent link="Revolute_6_1"/>
  <child link="end_effector_1"/>
  <axis xyz="0.0 0.0 1.0"/>
</joint>

<joint name="Revolute_5" type="continuous">
  <origin xyz="-0.035 0.0 0.11" rpy="0 0 0"/>
  <parent link="Revolute_5_1"/>
  <child link="Revolute_6_1"/>
  <axis xyz="1.0 0.0 0.0"/>

</joint>

<!-- <joint name="Revolute_2" type="revolute">
  <origin xyz="-0.188 0.0 0.138566" rpy="0 0 0"/>
  <parent link="Revolute_2_1"/>
  <child link="Revolute_3_1"/>
  <axis xyz="-1.0 0.0 0.0"/>
  <limit upper="1.919862" lower="-1.919862" effort="100" velocity="100"/>
</joint>

<joint name="Revolute_3" type="continuous">
  <origin xyz="0.1 0.0 0.29" rpy="0 0 0"/>
  <parent link="Revolute_3_1"/>
  <child link="Revolute_4_1"/>
  <axis xyz="1.0 0.0 0.0"/>
</joint>

<joint name="Revolute_4" type="continuous">
  <origin xyz="0.087934 0.0 0.223934" rpy="0 0 0"/>
  <parent link="Revolute_4_1"/>
  <child link="Revolute_5_1"/>
  <axis xyz="0.0 0.0 1.0"/>
</joint>

<joint name="Revolute_7" type="continuous">
  <origin xyz="0.035 0.0 0.03" rpy="0 0 0"/>
  <parent link="Revolute_6_1"/>
  <child link="end_effector_1"/>
  <axis xyz="0.0 0.0 1.0"/>
</joint>

<joint name="Revolute_5" type="revolute">
  <origin xyz="-0.035 0.0 0.11" rpy="0 0 0"/>
  <parent link="Revolute_5_1"/>
  <child link="Revolute_6_1"/>
  <axis xyz="1.0 0.0 0.0"/>
  <limit upper="1.919862" lower="-1.919862" effort="100" velocity="100"/>
</joint> -->

</robot>
